Workbook

Sheet Toyota Motor Corporation (TM)
A1: Date | B1: Open | C1: High | D1: Low | E1: Close | F1: Adj Close | G1: Volume
A2: 46091 | B2: 222.42 | C2: 224.96 | D2: 220.81 | E2: 221.01 | F2: 221.01 | G2: 215636 | I2: yahoo.finance
A3: 46090 | B3: 216.17 | C3: 224.98 | D3: 213.85 | E3: 221.01 | F3: 221.01 | G3: 539900
A4: 46083 | B4: 242.99 | C4: 244 | D4: 217.08 | E4: 219.14 | F4: 219.14 | G4: 2236900
A5: 46076 | B5: 237.95 | C5: 244.24 | D5: 235.72 | E5: 242.38 | F5: 242.38 | G5: 1208500 | I5: Toyota Motor Corporation (TM)
A6: 46069 | B6: 243.49 | C6: 245.52 | D6: 234.13 | E6: 239.6 | F6: 239.6 | G6: 1009400
A7: 46062 | B7: 239.92 | C7: 248.9 | D7: 238.22 | E7: 248.29 | F7: 248.29 | G7: 1495200
A8: 46055 | B8: 229.1 | C8: 246.36 | D8: 228.07 | E8: 244.22 | F8: 244.22 | G8: 1861000
A9: 46048 | B9: 225 | C9: 228.05 | D9: 217.48 | E9: 226.86 | F9: 226.86 | G9: 1686100
A10: 46041 | B10: 222.5 | C10: 228.46 | D10: 220.09 | E10: 226.28 | F10: 226.28 | G10: 1091900
A11: 46034 | B11: 221.97 | C11: 235.64 | D11: 221.6 | E11: 231.42 | F11: 231.42 | G11: 1625000
A12: 46027 | B12: 218 | C12: 222.34 | D12: 211 | E12: 221.52 | F12: 221.52 | G12: 1849900
A13: 46020 | B13: 215.67 | C13: 217.87 | D13: 214.06 | E13: 217.87 | F13: 217.87 | G13: 861100
A14: 46013 | B14: 219.08 | C14: 220.31 | D14: 215 | E14: 216.62 | F14: 216.62 | G14: 885700
A15: 46006 | B15: 215.25 | C15: 220.56 | D15: 214 | E15: 219.38 | F15: 219.38 | G15: 1814000
A16: 45999 | B16: 196.37 | C16: 209.43 | D16: 195 | E16: 208.12 | F16: 208.12 | G16: 1868800
A17: 45992 | B17: 199.13 | C17: 200.33 | D17: 192.71 | E17: 196.56 | F17: 196.56 | G17: 1643600
... A55: 45726 | B55: 185.69 | C55: 186.88 | D55: 182.28 | E55: 186.67 | F55: 183.07 | G55: 1188700

Sheet Volkswagen AG (VOW3.DE)
A1: Date | B1: Open | C1: High | D1: Low | E1: Close | F1: Adj Close | G1: Volume
A2: 46092 | B2: 90.06 | C2: 92.1 | D2: 89.96 | E2: 90.66 | F2: 90.66 | G2: 411024 | I2: yahoo.finance
A3: 46090 | B3: 90 | C3: 91.6 | D3: 87.6 | E3: 90.3 | F3: 90.3 | G3: 2952318
A4: 46083 | B4: 98.5 | C4: 98.56 | D4: 89.54 | E4: 89.98 | F4: 89.98 | G4: 6448205
A5: 46076 | B5: 102.85 | C5: 102.85 | D5: 99.82 | E5: 101.2 | F5: 101.2 | G5: 3642827 | I5: Volkswagen AG (VOW3.DE)
A6: 46069 | B6: 103 | C6: 105 | D6: 101 | E6: 102.5 | F6: 102.5 | G6: 3762112
A7: 46062 | B7: 100.85 | C7: 104.85 | D7: 100.8 | E7: 103.1 | F7: 103.1 | G7: 3544713
A8: 46055 | B8: 101.8 | C8: 106.3 | D8: 99.04 | E8: 100.75 | F8: 100.75 | G8: 4489633
A9: 46048 | B9: 104.9 | C9: 105.45 | D9: 101.2 | E9: 102.65 | F9: 102.65 | G9: 3391439
A10: 46041 | B10: 97.5 | C10: 106.15 | D10: 95.9 | E10: 105.5 | F10: 105.5 | G10: 5766886
A11: 46034 | B11: 103.9 | C11: 104.7 | D11: 100.45 | E11: 101.4 | F11: 101.4 | G11: 4379027
A12: 46027 | B12: 106.2 | C12: 106.6 | D12: 99.86 | E12: 103.85 | F12: 103.85 | G12: 3882188
A13: 46020 | B13: 103.4 | C13: 106.45 | D13: 102.4 | E13: 106.45 | F13: 106.45 | G13: 1713626
A14: 46013 | B14: 104.3 | C14: 104.9 | D14: 103.1 | E14: 103.75 | F14: 103.75 | G14: 835125
A15: 46006 | B15: 108.6 | C15: 108.65 | D15: 103.85 | E15: 104.05 | F15: 104.05 | G15: 2150101
A16: 45999 | B16: 106.9 | C16: 108.9 | D16: 105.95 | E16: 108.6 | F16: 108.6 | G16: 2844891
A17: 45992 | B17: 98.14 | C17: 107.3 | D17: 98.02 | E17: 106.9 | F17: 106.9 | G17: 6247158
... A55: 45726 | B55: 110 | C55: 114.2 | D55: 105.8 | E55: 107.65 | F55: 100.99 | G55: 7165483

Sheet Combine
A1: Date | B1: Toyota Motor Corporation (TM) | C1: Volkswagen AG (VOW3.DE) | D1: Weekly return Toyota | E1: Weekly return (Volkswagen) | H1: Data Descriptions
A2: 46091 | B2: =ifna(VLOOKUP(A2,'Toyota Motor Corporation (TM)'!A:F,6,0),"") -> 221.01 | C2: 90.66 | D2: =ifna(B2/B3-1,"") -> 0 | E2: =ifna(C2/C3-1,"") -> 0.003986711 | I2: =B1 -> Toyota Motor Corporation (TM) | J2: =C1 -> Volkswagen AG (VOW3.DE)
A3: 46090 | B3: =ifna(VLOOKUP(A3,'Toyota Motor Corporation (TM)'!A:F,6,0),"") -> 221.01 | C3: =ifna(VLOOKUP(A3,'Volkswagen AG (VOW3.DE)'!A:F,6,0),"") -> 90.3 | D3: =ifna(B3/B4-1,"") -> 0.0085333577 | E3: =ifna(C3/C4-1,"") -> 0.0035563459
A4: 46083 | B4: =ifna(VLOOKUP(A4,'Toyota Motor Corporation (TM)'!A:F,6,0),"") -> 219.14 | C4: =ifna(VLOOKUP(A4,'Volkswagen AG (VOW3.DE)'!A:F,6,0),"") -> 89.98 | D4: =ifna(B4/B5-1,"") -> -0.095882499 | E4: =ifna(C4/C5-1,"") -> -0.11086957 | H4: Max | I4: =MAX(D:D) -> 0.11764008 | J4: =MAX(E:E) -> 0.1110496
A5: 46076 | B5: =ifna(VLOOKUP(A5,'Toyota Motor Corporation (TM)'!A:F,6,0),"") -> 242.38 | C5: =ifna(VLOOKUP(A5,'Volkswagen AG (VOW3.DE)'!A:F,6,0),"") -> 101.2 | D5: =ifna(B5/B6-1,"") -> 0.011602671 | E5: =ifna(C5/C6-1,"") -> -0.012682927 | H5: MIn | I5: =MIN(D:D) -> -0.11411651 | J5: =MIN(E:E) -> -0.11150972
A6: 46069 | B6: =ifna(VLOOKUP(A6,'Toyota Motor Corporation (TM)'!A:F,6,0),"") -> 239.6 | C6: =ifna(VLOOKUP(A6,'Volkswagen AG (VOW3.DE)'!A:F,6,0),"") -> 102.5 | D6: =ifna(B6/B7-1,"") -> -0.034999396 | E6: =ifna(C6/C7-1,"") -> -0.0058195926 | H6: Range | I6: =I4-I5 -> 0.23175659 | J6: =J4-J5 -> 0.22255932
A7: 46062 | B7: =ifna(VLOOKUP(A7,'Toyota Motor Corporation (TM)'!A:F,6,0),"") -> 248.29 | C7: =ifna(VLOOKUP(A7,'Volkswagen AG (VOW3.DE)'!A:F,6,0),"") -> 103.1 | D7: =ifna(B7/B8-1,"") -> 0.016665302 | E7: =ifna(C7/C8-1,"") -> 0.023325062
A8: 46055 | B8: =ifna(VLOOKUP(A8,'Toyota Motor Corporation (TM)'!A:F,6,0),"") -> 244.22 | C8: =ifna(VLOOKUP(A8,'Volkswagen AG (VOW3.DE)'!A:F,6,0),"") -> 100.75 | D8: =ifna(B8/B9-1,"") -> 0.076522966 | E8: =ifna(C8/C9-1,"") -> -0.018509498 | H8: Q3 | I8: =_xlfn.PERCENTILE.INC(D:D,0.75) -> 0.026611535 | J8: =_xlfn.PERCENTILE.INC(E:E,0.75) -> 0.030237723
A9: 46048 | B9: =ifna(VLOOKUP(A9,'Toyota Motor Corporation (TM)'!A:F,6,0),"") -> 226.86 | C9: =ifna(VLOOKUP(A9,'Volkswagen AG (VOW3.DE)'!A:F,6,0),"") -> 102.65 | D9: =ifna(B9/B10-1,"") -> 0.002563196 | E9: =ifna(C9/C10-1,"") -> -0.027014218 | H9: Q1 | I9: =_xlfn.PERCENTILE.INC(D:D, 0.25) -> -0.024500624 | J9: =_xlfn.PERCENTILE.INC(E:E, 0.25) -> -0.029331887
A10: 46041 | B10: =ifna(VLOOKUP(A10,'Toyota Motor Corporation (TM)'!A:F,6,0),"") -> 226.28 | C10: =ifna(VLOOKUP(A10,'Volkswagen AG (VOW3.DE)'!A:F,6,0),"") -> 105.5 | D10: =ifna(B10/B11-1,"") -> -0.022210699 | E10: =ifna(C10/C11-1,"") -> 0.040433925 | H10: IQR | I10: =I8-I9 -> 0.051112159 | J10: =J8-J9 -> 0.05956961
A11: 46034 | B11: =ifna(VLOOKUP(A11,'Toyota Motor Corporation (TM)'!A:F,6,0),"") -> 231.42 | C11: =ifna(VLOOKUP(A11,'Volkswagen AG (VOW3.DE)'!A:F,6,0),"") -> 101.4 | D11: =ifna(B11/B12-1,"") -> 0.044691224 | E11: =ifna(C11/C12-1,"") -> -0.023591719 | H11: Fence | I11: =I10*1.5 -> 0.076668239 | J11: =J10*1.5 -> 0.089354415
A12: 46027 | B12: =ifna(VLOOKUP(A12,'Toyota Motor Corporation (TM)'!A:F,6,0),"") -> 221.52 | C12: =ifna(VLOOKUP(A12,'Volkswagen AG (VOW3.DE)'!A:F,6,0),"") -> 103.85 | D12: =ifna(B12/B13-1,"") -> 0.01675311 | E12: =ifna(C12/C13-1,"") -> -0.024424612 | H12: Upper Fence | I12: =I11+I8 -> 0.10327977 | J12: =J11+J8 -> 0.11959214
A13: 46020 | B13: =ifna(VLOOKUP(A13,'Toyota Motor Corporation (TM)'!A:F,6,0),"") -> 217.87 | C13: =ifna(VLOOKUP(A13,'Volkswagen AG (VOW3.DE)'!A:F,6,0),"") -> 106.45 | D13: =ifna(B13/B14-1,"") -> 0.0057704736 | E13: =ifna(C13/C14-1,"") -> 0.026024096 | H13: Lower fence | I13: =I9-I11 -> -0.10116886 | J13: =J9-J11 -> -0.1186863
A14: 46013 | B14: =ifna(VLOOKUP(A14,'Toyota Motor Corporation (TM)'!A:F,6,0),"") -> 216.62 | C14: =ifna(VLOOKUP(A14,'Volkswagen AG (VOW3.DE)'!A:F,6,0),"") -> 103.75 | D14: =ifna(B14/B15-1,"") -> -0.01258091 | E14: =ifna(C14/C15-1,"") -> -0.0028832292 | H14: Mean | I14: =AVERAGE(D:D) -> 0.0040837787 | J14: =AVERAGE(E:E) -> -0.00079043878
A15: 46006 | B15: =ifna(VLOOKUP(A15,'Toyota Motor Corporation (TM)'!A:F,6,0),"") -> 219.38 | C15: =ifna(VLOOKUP(A15,'Volkswagen AG (VOW3.DE)'!A:F,6,0),"") -> 104.05 | D15: =ifna(B15/B16-1,"") -> 0.054103402 | E15: =ifna(C15/C16-1,"") -> -0.041896869 | H15: Z min | I15: =(I5-I14)/I19 -> -2.7159624 | J15: =(J5-J14)/J19 -> -2.2413427
A16: 45999 | B16: =ifna(VLOOKUP(A16,'Toyota Motor Corporation (TM)'!A:F,6,0),"") -> 208.12 | C16: =ifna(VLOOKUP(A16,'Volkswagen AG (VOW3.DE)'!A:F,6,0),"") -> 108.6 | D16: =ifna(B16/B17-1,"") -> 0.058811559 | E16: =ifna(C16/C17-1,"") -> 0.015902713 | H16: Zmax | I16: =(I4-I14)/I19 -> 2.6092546 | J16: =(J4-J14)/J19 -> 2.2640308
A17: 45992 | B17: =ifna(VLOOKUP(A17,'Toyota Motor Corporation (TM)'!A:F,6,0),"") -> 196.56 | C17: =ifna(VLOOKUP(A17,'Volkswagen AG (VOW3.DE)'!A:F,6,0),"") -> 106.9 | D17: =ifna(B17/B18-1,"") -> -0.026304057 | E17: =ifna(C17/C18-1,"") -> 0.086602968 | H17: Mean absolute deviation | I17: =AVEDEV(D:D)*54/53 -> 0.034102945 | J17: =AVEDEV(E:E)*54/53 -> 0.039549002
A18: 45985 | B18: =ifna(VLOOKUP(A18,'Toyota Motor Corporation (TM)'!A:F,6,0),"") -> 201.87 | C18: =ifna(VLOOKUP(A18,'Volkswagen AG (VOW3.DE)'!A:F,6,0),"") -> 98.38 | D18: =ifna(B18/B19-1,"") -> 0.02150592 | E18: =ifna(C18/C19-1,"") -> 0.038640203 | H18: Sample Varience | I18: =VAR(D:D) -> 0.0018940418 | J18: =VAR(E:E) -> 0.0024402255
A19: 45978 | B19: =ifna(VLOOKUP(A19,'Toyota Motor Corporation (TM)'!A:F,6,0),"") -> 197.62 | C19: =ifna(VLOOKUP(A19,'Volkswagen AG (VOW3.DE)'!A:F,6,0),"") -> 94.72 | D19: =ifna(B19/B20-1,"") -> -0.031654253 | E19: =ifna(C19/C20-1,"") -> -0.030104444 | H19: Sample Standard deviation | I19: =_xlfn.STDEV.S(D:D) -> 0.043520591 | J19: =_xlfn.STDEV.S(E:E) -> 0.049398638
A20: 45971 | B20: =ifna(VLOOKUP(A20,'Toyota Motor Corporation (TM)'!A:F,6,0),"") -> 204.08 | C20: =ifna(VLOOKUP(A20,'Volkswagen AG (VOW3.DE)'!A:F,6,0),"") -> 97.66 | D20: =ifna(B20/B21-1,"") -> 0.010397069 | E20: =ifna(C20/C21-1,"") -> 0.052143935 | H20: CV | I20: =I19/I14 -> 10.656941 | J20: =J19/J14 -> -62.495211
A21: 45964 | B21: =ifna(VLOOKUP(A21,'Toyota Motor Corporation (TM)'!A:F,6,0),"") -> 201.98 | C21: =ifna(VLOOKUP(A21,'Volkswagen AG (VOW3.DE)'!A:F,6,0),"") -> 92.82 | D21: =ifna(B21/B22-1,"") -> -0.010823253 | E21: =ifna(C21/C22-1,"") -> 0.028818444
A22: 45957 | B22: =ifna(VLOOKUP(A22,'Toyota Motor Corporation (TM)'!A:F,6,0),"") -> 204.19 | C22: =ifna(VLOOKUP(A22,'Volkswagen AG (VOW3.DE)'!A:F,6,0),"") -> 90.22 | D22: =ifna(B22/B23-1,"") -> -0.0057457272 | E22: =ifna(C22/C23-1,"") -> -0.0033141847
A23: 45950 | B23: =ifna(VLOOKUP(A23,'Toyota Motor Corporation (TM)'!A:F,6,0),"") -> 205.37 | C23: =ifna(VLOOKUP(A23,'Volkswagen AG (VOW3.DE)'!A:F,6,0),"") -> 90.52 | D23: =ifna(B23/B24-1,"") -> 0.038113532 | E23: =ifna(C23/C24-1,"") -> -0.0074561404 | H23: Covarience | I23: =_xlfn.COVARIANCE.S(D:D,E:E) -> 0.0011152706
A24: 45943 | B24: =ifna(VLOOKUP(A24,'Toyota Motor Corporation (TM)'!A:F,6,0),"") -> 197.83 | C24: =ifna(VLOOKUP(A24,'Volkswagen AG (VOW3.DE)'!A:F,6,0),"") -> 91.2 | D24: =ifna(B24/B25-1,"") -> 0.068081201 | E24: =ifna(C24/C25-1,"") -> 0.022880215 | H24: Correlation | I24: =CORREL(D:D,E:E) -> 0.52049033
A25: 45936 | B25: =ifna(VLOOKUP(A25,'Toyota Motor Corporation (TM)'!A:F,6,0),"") -> 185.22 | C25: =ifna(VLOOKUP(A25,'Volkswagen AG (VOW3.DE)'!A:F,6,0),"") -> 89.16 | D25: =ifna(B25/B26-1,"") -> -0.048152526 | E25: =ifna(C25/C26-1,"") -> -0.044168096
A26: 45929 | B26: =ifna(VLOOKUP(A26,'Toyota Motor Corporation (TM)'!A:F,6,0),"") -> 194.59 | C26: =ifna(VLOOKUP(A26,'Volkswagen AG (VOW3.DE)'!A:F,6,0),"") -> 93.28 | D26: =ifna(B26/B27-1,"") -> -0.017718324 | E26: =ifna(C26/C27-1,"") -> 0.029353344
A27: 45922 | B27: =ifna(VLOOKUP(A27,'Toyota Motor Corporation (TM)'!A:F,6,0),"") -> 198.1 | C27: =ifna(VLOOKUP(A27,'Volkswagen AG (VOW3.DE)'!A:F,6,0),"") -> 90.62 | D27: =ifna(B27/B28-1,"") -> -0.0042724303 | E27: =ifna(C27/C28-1,"") -> -0.068462171
A28: 45915 | B28: =ifna(VLOOKUP(A28,'Toyota Motor Corporation (TM)'!A:F,6,0),"") -> 198.95 | C28: =ifna(VLOOKUP(A28,'Volkswagen AG (VOW3.DE)'!A:F,6,0),"") -> 97.28 | D28: =ifna(B28/B29-1,"") -> 0.014378219 | E28: =ifna(C28/C29-1,"") -> -0.04627451
A29: 45908 | B29: =ifna(VLOOKUP(A29,'Toyota Motor Corporation (TM)'!A:F,6,0),"") -> 196.13 | C29: =ifna(VLOOKUP(A29,'Volkswagen AG (VOW3.DE)'!A:F,6,0),"") -> 102 | D29: =ifna(B29/B30-1,"") -> -0.017483218 | E29: =ifna(C29/C30-1,"") -> 0.020816653
A30: 45901 | B30: =ifna(VLOOKUP(A30,'Toyota Motor Corporation (TM)'!A:F,6,0),"") -> 199.62 | C30: =ifna(VLOOKUP(A30,'Volkswagen AG (VOW3.DE)'!A:F,6,0),"") -> 99.92 | D30: =ifna(B30/B31-1,"") -> 0.025954669 | E30: =ifna(C30/C31-1,"") -> -0.0032917706
A31: 45894 | B31: =ifna(VLOOKUP(A31,'Toyota Motor Corporation (TM)'!A:F,6,0),"") -> 194.57 | C31: =ifna(VLOOKUP(A31,'Volkswagen AG (VOW3.DE)'!A:F,6,0),"") -> 100.25 | D31: =ifna(B31/B32-1,"") -> -0.033768685 | E31: =ifna(C31/C32-1,"") -> -0.020996094
A32: 45887 | B32: =ifna(VLOOKUP(A32,'Toyota Motor Corporation (TM)'!A:F,6,0),"") -> 201.37 | C32: =ifna(VLOOKUP(A32,'Volkswagen AG (VOW3.DE)'!A:F,6,0),"") -> 102.4 | D32: =ifna(B32/B33-1,"") -> 0.039812042 | E32: =ifna(C32/C33-1,"") -> 0.029973848
A33: 45880 | B33: =ifna(VLOOKUP(A33,'Toyota Motor Corporation (TM)'!A:F,6,0),"") -> 193.66 | C33: =ifna(VLOOKUP(A33,'Volkswagen AG (VOW3.DE)'!A:F,6,0),"") -> 99.42 | D33: =ifna(B33/B34-1,"") -> 0.026611535 | E33: =ifna(C33/C34-1,"") -> 0.042356888
A34: 45873 | B34: =ifna(VLOOKUP(A34,'Toyota Motor Corporation (TM)'!A:F,6,0),"") -> 188.64 | C34: =ifna(VLOOKUP(A34,'Volkswagen AG (VOW3.DE)'!A:F,6,0),"") -> 95.38 | D34: =ifna(B34/B35-1,"") -> 0.049808003 | E34: =ifna(C34/C35-1,"") -> 0.069762225
A35: 45866 | B35: =ifna(VLOOKUP(A35,'Toyota Motor Corporation (TM)'!A:F,6,0),"") -> 179.69 | C35: =ifna(VLOOKUP(A35,'Volkswagen AG (VOW3.DE)'!A:F,6,0),"") -> 89.16 | D35: =ifna(B35/B36-1,"") -> -0.046686827 | E35: =ifna(C35/C36-1,"") -> -0.11150972
A36: 45859 | B36: =ifna(VLOOKUP(A36,'Toyota Motor Corporation (TM)'!A:F,6,0),"") -> 188.49 | C36: =ifna(VLOOKUP(A36,'Volkswagen AG (VOW3.DE)'!A:F,6,0),"") -> 100.35 | D36: =ifna(B36/B37-1,"") -> 0.11764008 | E36: =ifna(C36/C37-1,"") -> 0.1110496
... A54: 45740 | B54: =ifna(VLOOKUP(A54,'Toyota Motor Corporation (TM)'!A:F,6,0),"") -> 175.61 | C54: =ifna(VLOOKUP(A54,'Volkswagen AG (VOW3.DE)'!A:F,6,0),"") -> 90.96 | D54: =ifna(B54/B55-1,"") -> -0.061009518 | E54: =ifna(C54/C55-1,"") -> -0.044337046
A55: 45733 | B55: =ifna(VLOOKUP(A55,'Toyota Motor Corporation (TM)'!A:F,6,0),"") -> 187.02 | C55: =ifna(VLOOKUP(A55,'Volkswagen AG (VOW3.DE)'!A:F,6,0),"") -> 95.18 | E55: =ifna(C55/C56-1,"") -> -0.057530449
A56: 45726 | C56: =ifna(VLOOKUP(A56,'Volkswagen AG (VOW3.DE)'!A:F,6,0),"") -> 100.99

Sheet S&P 500
A1: Date | B1: Adj Close | C1: Weekly return | G1: Date | H1: Open | I1: High | J1: Low | K1: Close | L1: Adj Close | M1: Volume
A2: 46090 | B2: 6781.48 | C2: =B2/B3-1 -> 0.0061513171 | G2: 46090 | H2: 6699.8 | I2: 6845.08 | J2: 6636.04 | K2: 6781.48 | L2: 6781.48 | M2: 12654360000
A3: 46083 | B3: 6740.02 | C3: =B3/B4-1 -> -0.020186426 | G3: 46083 | H3: 6824.36 | I3: 6901.01 | J3: 6710.42 | K3: 6740.02 | L3: 6740.02 | M3: 29555750000
A4: 46076 | B4: 6878.88 | C4: =B4/B5-1 -> -0.0044330206 | G4: 46076 | H4: 6901.25 | I4: 6952.51 | J4: 6815.43 | K4: 6878.88 | L4: 6878.88 | M4: 28787710000
A5: 46069 | B5: 6909.51 | C5: =B5/B6-1 -> 0.010728229 | G5: 46069 | H5: 6819.86 | I5: 6915.86 | J5: 6775.5 | K5: 6909.51 | L5: 6909.51 | M5: 21100810000
A6: 46062 | B6: 6836.17 | C6: =B6/B7-1 -> -0.013866971 | G6: 46062 | H6: 6917.26 | I6: 6993.48 | J6: 6794.55 | K6: 6836.17 | L6: 6836.17 | M6: 30258780000
A7: 46055 | B7: 6932.3 | C7: =B7/B8-1 -> -0.00096987619 | G7: 46055 | H7: 6916.64 | I7: 6993.08 | J7: 6780.13 | K7: 6932.3 | L7: 6932.3 | M7: 33538260000
A8: 46048 | B8: 6939.03 | C8: =B8/B9-1 -> 0.0033865415 | G8: 46048 | H8: 6923.23 | I8: 7002.28 | J8: 6870.8 | K8: 6939.03 | L8: 6939.03 | M8: 29382560000
A9: 46041 | B9: 6915.61 | C9: =B9/B10-1 -> -0.0035158451 | G9: 46041 | H9: 6865.24 | I9: 6934.75 | J9: 6789.05 | K9: 6915.61 | L9: 6915.61 | M9: 21784530000
A10: 46034 | B10: 6940.01 | C10: =B10/B11-1 -> -0.0037710227 | G10: 46034 | H10: 6944.12 | I10: 6986.33 | J10: 6885.74 | K10: 6940.01 | L10: 6940.01 | M10: 26112200000
A11: 46027 | B11: 6966.28 | C11: =B11/B12-1 -> 0.015719249 | G11: 46027 | H11: 6892.19 | I11: 6978.36 | J11: 6891.56 | K11: 6966.28 | L11: 6966.28 | M11: 26993190000
A12: 46020 | B12: 6858.47 | C12: =B12/B13-1 -> -0.010313221 | G12: 46020 | H12: 6903.6 | I12: 6920.21 | J12: 6824.31 | K12: 6858.47 | L12: 6858.47 | M12: 14297630000
A13: 46013 | B13: 6929.94 | C13: =B13/B14-1 -> 0.013964445 | G13: 46013 | H13: 6865.21 | I13: 6945.77 | J13: 6855.74 | K13: 6929.94 | L13: 6929.94 | M13: 12670410000
... A53: 45733 | B53: 5667.56 | C53: =B53/B54-1 -> 0.005075422 | G53: 45733 | H53: 5635.6 | I53: 5715.33 | J53: 5597.76 | K53: 5667.56 | L53: 5667.56 | M53: 28404010000
A54: 45726 | B54: 5638.94 | G54: 45726 | H54: 5603.65 | I54: 5645.27 | J54: 5504.65 | K54: 5638.94 | L54: 5638.94 | M54: 21323230000

Sheet Sharpe Ratio and Comparison of 
A1: Sharpe Ratio
B3: =Combine!B1 -> Toyota Motor Corporation (TM) | C3: =Combine!C1 -> Volkswagen AG (VOW3.DE)
A4: Sharpe Ratio | B4: =(Combine!I14-B7)/Combine!I19 -> 0.076337205 | C4: =(Combine!J14-B7)/Combine!J19 -> -0.031417409
A6: One year T.Bill | B6: 0.0396
A7: One week T.Bill | B7: =B6/52 -> 0.00076153846
A12: Comparison of risk (Variance)
A13: Spotify | B13: V
A14: 122870 KQ | B14: T
A15: H0: | B15: σ^2(T)​=σ^2(V)​
A16: HA: | B16: σ^2(T) >​σ^2(V)​
A18: n | B18: 54
A19: df1 | B19: 53
A20: df2 | B20: 53
A21: F(df1, df2) | B21: S(T)/S(V)
A22: F(53, 53) | B22: =Combine!J18/Combine!I18 -> 1.2883694
A23: P | B23: =_xlfn.F.DIST.RT(B22,53,53) -> 0.17963684
A24: Fails to reject H0 at 5% significane level

Sheet Regression
A1: Date | B1: Toyota | C1: S&P 500 | G1: SUMMARY OUTPUT
A2: 46091 | B2: =ifna(VLOOKUP(A2, Combine!A2:F58,4,0),"") -> 0 | C2: 0.0061513171
A3: 46090 | B3: =ifna(VLOOKUP(A3, Combine!A3:F59,4,0),"") -> 0.0085333577 | C3: -0.020186426 | G3: Regression Statistics
A4: 46083 | B4: =ifna(VLOOKUP(A4, Combine!A4:F60,4,0),"") -> -0.095882499 | C4: -0.0044330206 | G4: Multiple R | H4: 0.25550538
A5: 46076 | B5: =ifna(VLOOKUP(A5, Combine!A5:F61,4,0),"") -> 0.011602671 | C5: 0.010728229 | G5: R Square | H5: 0.065283002
A6: 46069 | B6: =ifna(VLOOKUP(A6, Combine!A6:F62,4,0),"") -> -0.034999396 | C6: -0.013866971 | G6: Adjusted R Square | H6: 0.046588662
A7: 46062 | B7: =ifna(VLOOKUP(A7, Combine!A7:F63,4,0),"") -> 0.016665302 | C7: -0.00096987619 | G7: Standard Error | H7: 0.041958387
A8: 46055 | B8: =ifna(VLOOKUP(A8, Combine!A8:F64,4,0),"") -> 0.076522966 | C8: 0.0033865415 | G8: Observations | H8: 52
A9: 46048 | B9: =ifna(VLOOKUP(A9, Combine!A9:F65,4,0),"") -> 0.002563196 | C9: -0.0035158451
A10: 46041 | B10: =ifna(VLOOKUP(A10, Combine!A10:F66,4,0),"") -> -0.022210699 | C10: -0.0037710227 | G10: ANOVA
A11: 46034 | B11: =ifna(VLOOKUP(A11, Combine!A11:F67,4,0),"") -> 0.044691224 | C11: 0.015719249 | H11: df | I11: SS | J11: MS | K11: F | L11: Significance F
A12: 46027 | B12: =ifna(VLOOKUP(A12, Combine!A12:F68,4,0),"") -> 0.01675311 | C12: -0.010313221 | G12: Regression | H12: 1 | I12: 0.006147911 | J12: 0.006147911 | K12: 3.4921266 | L12: 0.067525167
A13: 46020 | B13: =ifna(VLOOKUP(A13, Combine!A13:F69,4,0),"") -> 0.0057704736 | C13: 0.013964445 | G13: Residual | H13: 50 | I13: 0.08802531 | J13: 0.001760506
A14: 46013 | B14: =ifna(VLOOKUP(A14, Combine!A14:F70,4,0),"") -> -0.01258091 | C14: 0.0010384611 | G14: Total | H14: 51 | I14: 0.094173221
A15: 46006 | B15: =ifna(VLOOKUP(A15, Combine!A15:F71,4,0),"") -> 0.054103402 | C15: -0.0062572776
A16: 45999 | B16: =ifna(VLOOKUP(A16, Combine!A16:F72,4,0),"") -> 0.058811559 | C16: 0.0031113622 | H16: Coefficients | I16: Standard Error | J16: t Stat | K16: P-value | L16: Lower 95% | M16: Upper 95% | N16: Lower 95.0% | O16: Upper 95.0%
A17: 45992 | B17: =ifna(VLOOKUP(A17, Combine!A17:F73,4,0),"") -> -0.026304057 | C17: 0.037270994 | G17: Intercept | H17: 0.0071733 | I17: 0.005901015 | J17: 1.2156046 | K17: 0.22984414 | L17: -0.004679236 | M17: 0.019025837 | N17: -0.004679236 | O17: 0.019025837
A18: 45985 | B18: =ifna(VLOOKUP(A18, Combine!A18:F74,4,0),"") -> 0.02150592 | C18: -0.019471021 | G18: X Variable 1 | H18: -0.4814094 | I18: 0.25761407 | J18: -1.8687233 | K18: 0.067525167 | L18: -0.99884248 | M18: 0.036023684 | N18: -0.99884248 | O18: 0.036023684
A19: 45978 | B19: =ifna(VLOOKUP(A19, Combine!A19:F75,4,0),"") -> -0.031654253 | C19: 0.00078914517
A20: 45971 | B20: =ifna(VLOOKUP(A20, Combine!A20:F76,4,0),"") -> 0.010397069 | C20: -0.016286074
A21: 45964 | B21: =ifna(VLOOKUP(A21, Combine!A21:F77,4,0),"") -> -0.010823253 | C21: 0.0071425521
A22: 45957 | B22: =ifna(VLOOKUP(A22, Combine!A22:F78,4,0),"") -> -0.0057457272 | C22: 0.019159635
A23: 45950 | B23: =ifna(VLOOKUP(A23, Combine!A23:F79,4,0),"") -> 0.038113532 | C23: 0.01701638
A24: 45943 | B24: =ifna(VLOOKUP(A24, Combine!A24:F80,4,0),"") -> 0.068081201 | C24: -0.024312851
A25: 45936 | B25: =ifna(VLOOKUP(A25, Combine!A25:F81,4,0),"") -> -0.048152526 | C25: 0.010850881
A26: 45929 | B26: =ifna(VLOOKUP(A26, Combine!A26:F82,4,0),"") -> -0.017718324 | C26: -0.0031000726
A27: 45922 | B27: =ifna(VLOOKUP(A27, Combine!A27:F83,4,0),"") -> -0.0042724303 | C27: 0.012160764
A28: 45915 | B28: =ifna(VLOOKUP(A28, Combine!A28:F84,4,0),"") -> 0.014378219 | C28: 0.015858983
A29: 45908 | B29: =ifna(VLOOKUP(A29, Combine!A29:F85,4,0),"") -> -0.017483218 | C29: 0.0032877934
A30: 45901 | B30: =ifna(VLOOKUP(A30, Combine!A30:F86,4,0),"") -> 0.025954669 | C30: -0.0010283118
... A53: 45747 | B53: =ifna(VLOOKUP(A53, Combine!A53:F109,4,0),"") -> -0.11411651 | C53: 0.005075422
A54: 45740 | B54: =ifna(VLOOKUP(A54, Combine!A54:F110,4,0),"") -> -0.061009518
B57: =ifna(VLOOKUP(A57, Combine!A57:F113,4,0),"")
B58: =ifna(VLOOKUP(A58, Combine!A58:F114,4,0),"")
B59: =ifna(VLOOKUP(A59, Combine!A59:F115,4,0),"")
B60: =ifna(VLOOKUP(A60, Combine!A60:F116,4,0),"")
B61: =ifna(VLOOKUP(A61, Combine!A61:F117,4,0),"")
B62: =ifna(VLOOKUP(A62, Combine!A62:F118,4,0),"")
B63: =ifna(VLOOKUP(A63, Combine!A63:F119,4,0),"")
B64: =ifna(VLOOKUP(A64, Combine!A64:F120,4,0),"")
...
